INFO:     Will watch for changes in these directories: ['/home/workspace']
INFO:     Uvicorn running on http://0.0.0.0:8000 (Press CTRL+C to quit)
INFO:     Started reloader process [183] using StatReload
INFO:     Started server process [188]
INFO:     Waiting for application startup.
INFO:     Application startup complete.
INFO:     172.20.0.1:54958 - "HEAD / HTTP/1.1" 405 Method Not Allowed
thon3.13/asyncio/runners.py", line 195, in run
    return runner.run(main)
           ~~~~~~~~~~^^^^^^
  File "/usr/local/lib/python3.13/asyncio/runners.py", line 118, in run
    return self._loop.run_until_complete(task)
           ~~~~~~~~~~~~~~~~~~~~~~~~~~~~~^^^^^^
  File "/usr/local/lib/python3.13/asyncio/base_events.py", line 725, in run_until_complete
    return future.result()
           ~~~~~~~~~~~~~^^
  File "/usr/local/lib/python3.13/site-packages/uvicorn/server.py", line 78, in serve
    await self.startup(sockets=sockets)
  File "/usr/local/lib/python3.13/site-packages/uvicorn/server.py", line 128, in startup
    server = await loop.create_server(
             ^^^^^^^^^^^^^^^^^^^^^^^^^
        create_protocol, sock=sock, ssl=config.ssl, backlog=config.backlog
        ^^^^^^^^^^^^^^^^^^^^^^^^^^^^^^^^^^^^^^^^^^^^^^^^^^^^^^^^^^^^^^^^^^
    )
    ^
  File "/usr/local/lib/python3.13/asyncio/base_events.py", line 1655, in create_server
    server._start_serving()
    ~~~~~~~~~~~~~~~~~~~~~^^
  File "/usr/local/lib/python3.13/asyncio/base_events.py", line 317, in _start_serving
    sock.listen(self._backlog)
    ~~~~~~~~~~~^^^^^^^^^^^^^^^
OSError: [Errno 98] Address already in use

During handling of the above exception, another exception occurred:

Traceback (most recent call last):
  File "/usr/local/lib/python3.13/site-packages/starlette/routing.py", line 686, in lifespan
    await receive()
  File "/usr/local/lib/python3.13/site-packages/uvicorn/lifespan/on.py", line 137, in receive
    return await self.receive_queue.get()
           ^^^^^^^^^^^^^^^^^^^^^^^^^^^^^^
  File "/usr/local/lib/python3.13/asyncio/queues.py", line 186, in get
    await getter
asyncio.exceptions.CancelledError

Process SpawnProcess-1:
Traceback (most recent call last):
  File "/usr/local/lib/python3.13/multiprocessing/process.py", line 313, in _bootstrap
    self.run()
    ~~~~~~~~^^
  File "/usr/local/lib/python3.13/multiprocessing/process.py", line 108, in run
    self._target(*self._args, **self._kwargs)
    ~~~~~~~~~~~~^^^^^^^^^^^^^^^^^^^^^^^^^^^^^
  File "/usr/local/lib/python3.13/site-packages/uvicorn/_subprocess.py", line 76, in subprocess_started
    target(sockets=sockets)
    ~~~~~~^^^^^^^^^^^^^^^^^
  File "/usr/local/lib/python3.13/site-packages/uvicorn/server.py", line 61, in run
    return asyncio.run(self.serve(sockets=sockets))
           ~~~~~~~~~~~^^^^^^^^^^^^^^^^^^^^^^^^^^^^^
  File "/usr/local/lib/python3.13/asyncio/runners.py", line 195, in run
    return runner.run(main)
           ~~~~~~~~~~^^^^^^
  File "/usr/local/lib/python3.13/asyncio/runners.py", line 118, in run
    return self._loop.run_until_complete(task)
           ~~~~~~~~~~~~~~~~~~~~~~~~~~~~~^^^^^^
  File "/usr/local/lib/python3.13/asyncio/base_events.py", line 725, in run_until_complete
    return future.result()
           ~~~~~~~~~~~~~^^
  File "/usr/local/lib/python3.13/site-packages/uvicorn/server.py", line 78, in serve
    await self.startup(sockets=sockets)
  File "/usr/local/lib/python3.13/site-packages/uvicorn/server.py", line 128, in startup
    server = await loop.create_server(
             ^^^^^^^^^^^^^^^^^^^^^^^^^
        create_protocol, sock=sock, ssl=config.ssl, backlog=config.backlog
        ^^^^^^^^^^^^^^^^^^^^^^^^^^^^^^^^^^^^^^^^^^^^^^^^^^^^^^^^^^^^^^^^^^
    )
    ^
  File "/usr/local/lib/python3.13/asyncio/base_events.py", line 1655, in create_server
    server._start_serving()
    ~~~~~~~~~~~~~~~~~~~~~^^
  File "/usr/local/lib/python3.13/asyncio/base_events.py", line 317, in _start_serving
    sock.listen(self._backlog)
    ~~~~~~~~~~~^^^^^^^^^^^^^^^
OSError: [Errno 98] Address already in use
